#VRML_SIM R2025a utf8

EXTERNPROTO "https://raw.githubusercontent.com/cyberbotics/webots/R2025a/projects/objects/backgrounds/protos/TexturedBackground.proto"
EXTERNPROTO "https://raw.githubusercontent.com/cyberbotics/webots/R2025a/projects/objects/backgrounds/protos/TexturedBackgroundLight.proto"
IMPORTABLE EXTERNPROTO "../protos/RigidBlock.proto"
EXTERNPROTO "https://raw.githubusercontent.com/cyberbotics/webots/R2025a/projects/objects/tables/protos/Table.proto"
EXTERNPROTO "https://raw.githubusercontent.com/cyberbotics/webots/R2025a/projects/robots/neuronics/ipr/protos/IprHd6m180.proto"

WorldInfo {
}
Viewpoint {
  orientation 0 0 -1 3.141592653589793
  position 4.205805383038536 0.014468724603526632 1.0511990585020545
}
TexturedBackground {
}
TexturedBackgroundLight {
}
Table {
}
IprHd6m180 {
  translation 0 0 0.74
  controller "touch_controller"
}
Solid {
  translation 0 -0.5 1.05
  children [
    Shape {
      geometry Box {
        size 0.5 0.2 0.7
      }
    }
  ]
  name "RigidBlock"
  boundingObject Box {
    size 0.5 0.2 0.7
  }
}
Solid {
  translation 0 0.5 1.09
  children [
    Solid {
      name "base"
      boundingObject Box {
        size 0.5 0.2 0.7
      }
      physics Physics {
        mass 1
      }
    }
    SliderJoint {
      jointParameters JointParameters {
        axis 1 0 0
        springConstant 100
        dampingConstant 5
      }
      endPoint Solid {
        children [
          Shape {
            geometry Box {
              size 0.5 0.2 0.7
            }
          }
        ]
        name "SpringBlock"
        boundingObject Box {
          size 0.5 0.2 0.7
        }
        physics Physics {
          mass 0.3
          damping Damping {
          }
        }
      }
    }
  ]
  name "SliderJoint"
  physics Physics {
  }
  locked TRUE
}
